Initializing LCNN model training...
Loading WaveFake dataset...
training_dataset size: 73360
validation_dataset size: 9170
test_dataset size: 9170
Set up the LCNN model...
Training started...
Training batches:   0%|                                                                                               | 0/287 [00:01<?, ?it/s]
Training Epochs:   0%|                                                                                                | 0/100 [00:01<?, ?it/s]
Traceback (most recent call last):
  File "/home/hessos4l/Downloads/DetectingVocoderFingerprints/src/training/train_model.py", line 195, in <module>
    for waveform, label in tqdm(train_loader, desc="Training batches"):
  File "/home/hessos4l/Downloads/DetectingVocoderFingerprints/myenv/lib/python3.9/site-packages/tqdm/std.py", line 1181, in __iter__
    for obj in iterable:
  File "/home/hessos4l/Downloads/DetectingVocoderFingerprints/myenv/lib/python3.9/site-packages/torch/utils/data/dataloader.py", line 630, in __next__
    data = self._next_data()
  File "/home/hessos4l/Downloads/DetectingVocoderFingerprints/myenv/lib/python3.9/site-packages/torch/utils/data/dataloader.py", line 1345, in _next_data
    return self._process_data(data)
  File "/home/hessos4l/Downloads/DetectingVocoderFingerprints/myenv/lib/python3.9/site-packages/torch/utils/data/dataloader.py", line 1371, in _process_data
    data.reraise()
  File "/home/hessos4l/Downloads/DetectingVocoderFingerprints/myenv/lib/python3.9/site-packages/torch/_utils.py", line 694, in reraise
    raise exception
RuntimeError: Caught RuntimeError in DataLoader worker process 0.
Original Traceback (most recent call last):
  File "/home/hessos4l/Downloads/DetectingVocoderFingerprints/myenv/lib/python3.9/site-packages/torch/utils/data/_utils/worker.py", line 308, in _worker_loop
    data = fetcher.fetch(index)
  File "/home/hessos4l/Downloads/DetectingVocoderFingerprints/myenv/lib/python3.9/site-packages/torch/utils/data/_utils/fetch.py", line 54, in fetch
    return self.collate_fn(data)
  File "/home/hessos4l/Downloads/DetectingVocoderFingerprints/myenv/lib/python3.9/site-packages/torch/utils/data/_utils/collate.py", line 265, in default_collate
    return collate(batch, collate_fn_map=default_collate_fn_map)
  File "/home/hessos4l/Downloads/DetectingVocoderFingerprints/myenv/lib/python3.9/site-packages/torch/utils/data/_utils/collate.py", line 142, in collate
    return [collate(samples, collate_fn_map=collate_fn_map) for samples in transposed]  # Backwards compatibility.
  File "/home/hessos4l/Downloads/DetectingVocoderFingerprints/myenv/lib/python3.9/site-packages/torch/utils/data/_utils/collate.py", line 142, in <listcomp>
    return [collate(samples, collate_fn_map=collate_fn_map) for samples in transposed]  # Backwards compatibility.
  File "/home/hessos4l/Downloads/DetectingVocoderFingerprints/myenv/lib/python3.9/site-packages/torch/utils/data/_utils/collate.py", line 119, in collate
    return collate_fn_map[elem_type](batch, collate_fn_map=collate_fn_map)
  File "/home/hessos4l/Downloads/DetectingVocoderFingerprints/myenv/lib/python3.9/site-packages/torch/utils/data/_utils/collate.py", line 161, in collate_tensor_fn
    out = elem.new(storage).resize_(len(batch), *list(elem.size()))
RuntimeError: Trying to resize storage that is not resizable
